<?xml version="1.0" ?>

<sdf version="1.5">
  <!-- http://sdformat.org/spec?elem=sensor&ver=1.5 -->
  <model name="tankbot">
    <link name="chassis">
      <pose>0 0 0.11 0 0 0</pose>
      <inertial>
        <pose>0.04650000000000001 0 0  0 0 0</pose>
        <mass>3.0</mass>
        <inertia>
          <ixx>0.012592666666666665</ixx>
          <iyy>0.04085416666666667</iyy>
          <izz>0.043813500000000005</izz>
          <ixy>0</ixy>
          <ixz>0</ixz>
          <iyz>0</iyz>
        </inertia>
      </inertial>
      <collision name="collision">
        <geometry>
          <box>
            <size>0.4 0.2 0.1</size>
          </box>
        </geometry>
      </collision>
      <visual name="visual">
        <geometry>
          <box>
            <size>0.4 0.2 0.1</size>
          </box>
        </geometry>
        <material>
          <script>
            <uri>file://media/materials/scripts/gazebo.material</uri>
            <ambient>0.46 0.46 0.46 1.0</ambient>
  		<diffuse>0.46 0.46 0.46 1.0</diffuse>
  		<specular>0.46 0.46 0.46 1.0</specular>
  		<emissive>0.46 0.46 0.46 1.0</emissive>
          </script>
        </material>
      </visual>
    </link>
    
    <link name="boarder">
        <pose>0.03650000000000001 0.0 0.2 0.0 0.0 0.0</pose>
        <inertial>
        <mass>0.15</mass>
        <inertia>
          <ixx>0.00018958333333333338</ixx>
          <iyy>0.00018958333333333338</iyy>
          <izz>0.00031250000000000006</izz>
          <ixy>0</ixy>
          <ixz>0</ixz>
          <iyz>0</iyz>
        </inertia>
      </inertial>
        <collision name="boarder">
          <geometry>
            <box>
              <size>0.3 0.2 .02</size>
            </box>
          </geometry>
        </collision>
        
        <visual name="visual">
          <geometry>
            <box>
              <size>0.3 0.2 .02</size>
            </box>
          </geometry>
           <material>
             <ambient>0.46 0.46 0.46 1.0</ambient>
             <diffuse>0.46 0.46 0.46 1.0</diffuse>
             <specular>0.46 0.46 0.46 1.0</specular>
             <emissive>0.46 0.46 0.46 1.0</emissive>
           </material>
        </visual>
      </link>
      <joint name="boarder_joint" type="fixed">
        <child>boarder</child>
        <parent>chassis</parent>
      </joint>

            
    <link name="wheel_fl">
      <pose>
        0.12 0.1100000000000002 0.05 -1.5707963267948966 0 0
      </pose>
      <inertial>
        <mass>0.25</mass>
        <inertia>
          <ixx>0.00018958333333333338</ixx>
          <iyy>0.00018958333333333338</iyy>
          <izz>0.00031250000000000006</izz>
          <ixy>0</ixy>
          <ixz>0</ixz>
          <iyz>0</iyz>
        </inertia>
      </inertial>
      <collision name="collision">
        <geometry>
          <cylinder>
            <radius>0.05</radius>
            <length>0.02</length>
          </cylinder>
        </geometry>
      </collision>
      <visual name="wheel_fl">
        <geometry>
          <cylinder>
            <radius>0.05</radius>
            <length>0.02</length>
          </cylinder>
        </geometry>
        <material>
          <script>
            <uri>file://media/materials/scripts/gazebo.material</uri>
            <name>Gazebo/Black</name>
          </script>
        </material>
      </visual>
    </link>
    
    <joint name="wheel_fl_drive" type="revolute">
      <parent>chassis</parent>
      <child>wheel_fl</child>
      <axis>
        <xyz>0 0 1</xyz>
      </axis>
    </joint>
    
    <link name="wheel_fl2">
      <pose>
        0.2 0.1100000000000002 0.13 -1.5707963267948966 0 0
      </pose>
      <inertial>
        <mass>0.25</mass>
        <inertia>
          <ixx>0.00018958333333333338</ixx>
          <iyy>0.00018958333333333338</iyy>
          <izz>0.00031250000000000006</izz>
          <ixy>0</ixy>
          <ixz>0</ixz>
          <iyz>0</iyz>
        </inertia>
      </inertial>
      <collision name="collision">
        <geometry>
          <cylinder>
            <radius>0.05</radius>
            <length>0.02</length>
          </cylinder>
        </geometry>
      </collision>
      <visual name="visual">
        <geometry>
          <cylinder>
            <radius>0.05</radius>
            <length>0.02</length>
          </cylinder>
        </geometry>
        <material>
          <script>
            <uri>file://media/materials/scripts/gazebo.material</uri>
            <name>Gazebo/Black</name>
          </script>
        </material>
      </visual>
    </link>
    
    <joint name="wheel_fl2_drive" type="revolute">
      <parent>chassis</parent>
      <child>wheel_fl2</child>
      <axis>
        <xyz>0 0 1</xyz>
      </axis>
    </joint>

	<!-- comment ->
    <link name="chain_l_up">
      <pose>
        0.0098 0.11 0.142
        0.0 -0.23 0.0
      </pose>
      <gravity>0</gravity>
      <collision name="collision">
        <geometry>
          <box>
            <size>0.35 0.02 0.005</size>
          </box>
        </geometry>
      </collision>
      <visual name="visual">
        <geometry>
          <box>
            <size>0.35 0.02 0.005</size>
          </box>
        </geometry>
        <material>
          <script>
            <uri>file://media/materials/scripts/gazebo.material</uri>
            <name>Gazebo/Grey</name>
          </script>
        </material>
      </visual>
    </link>
    
            <joint name="chain_l_up_joint" type="fixed">
      <parent>boarder</parent>
      <child>chain_l_up</child>
    </joint>
    
        <link name="chain_r_up">
      <pose>
        0.0098 -0.11 0.142
        0 -0.23 0.0
      </pose>
      <gravity>0</gravity>
      <collision name="collision">
        <geometry>
          <box>
            <size>0.35 0.02 0.005</size>
          </box>
        </geometry>
      </collision>
      <visual name="visual">
        <geometry>
          <box>
            <size>0.35 0.02 0.005</size>
          </box>
        </geometry>
        <material>
          <script>
            <uri>file://media/materials/scripts/gazebo.material</uri>
            <name>Gazebo/Grey</name>
          </script>
        </material>
      </visual>
    </link>
    
    <joint name="chain_r_up_joint" type="fixed">
      <parent>chassis</parent>
      <child>chain_r_up</child>
    </joint>
    
    
        <link name="chain_l_down">
      <pose>
        -0.006 0.11 0.008
        0.0 0.0 0.0
      </pose>
      <gravity>0</gravity>
      <collision name="collision">
        <geometry>
          <box>
            <size>0.19 0.02 0.005</size>
          </box>
        </geometry>
      </collision>
      <visual name="visual">
        <geometry>
          <box>
            <size>0.19 0.02 0.005</size>
          </box>
        </geometry>
        <material>
          <script>
            <uri>file://media/materials/scripts/gazebo.material</uri>
            <name>Gazebo/Grey</name>
          </script>
        </material>
      </visual>
    </link>
    
        <joint name="chain_l_down_joint" type="fixed">
      <parent>chassis</parent>
      <child>chain_l_down</child>
    </joint>
    
    
    <link name="chain_l_front">
      <pose>
        0.2 0.11 0.05
        0.0 -0.8 0.0
      </pose>
      <gravity>0</gravity>
      <collision name="collision">
        <geometry>
          <box>
            <size>0.09 0.02 0.005</size>
          </box>
        </geometry>
      </collision>
      <visual name="visual">
        <geometry>
          <box>
            <size>0.09 0.02 0.005</size>
          </box>
        </geometry>
        <material>
          <script>
            <uri>file://media/materials/scripts/gazebo.material</uri>
            <name>Gazebo/Grey</name>
          </script>
        </material>
      </visual>
    </link>
    
            <joint name="chain_l_front_joint" type="fixed">
      <parent>chassis</parent>
      <child>chain_l_front</child>
    </joint>
    
      <link name="chain_r_down">
      <pose>
        -0.006 -0.11 0.008
        0.0 0.0 0.0
      </pose>
      <gravity>0</gravity>
      <collision name="collision">
        <geometry>
          <box>
            <size>0.19 0.02 0.005</size>
          </box>
        </geometry>
      </collision>
      <visual name="visual">
        <geometry>
          <box>
            <size>0.19 0.02 0.005</size>
          </box>
        </geometry>
        <material>
          <script>
            <uri>file://media/materials/scripts/gazebo.material</uri>
            <name>Gazebo/Grey</name>
          </script>
        </material>
      </visual>
    </link>
    
            <joint name="chain_r_down_joint" type="fixed">
      <parent>chassis</parent>
      <child>chain_r_down</child>
    </joint>
    
   <link name="chain_r_front">
      <pose>
        0.2 -0.11 0.05
        0.0 -0.8 0.0
      </pose>
      <gravity>0</gravity>
      <collision name="collision">
        <geometry>
          <box>
            <size>0.1 0.02 0.005</size>
          </box>
        </geometry>
      </collision>
      <visual name="visual">
        <geometry>
          <box>
            <size>0.1 0.02 0.005</size>
          </box>
        </geometry>
        <material>
          <script>
            <uri>file://media/materials/scripts/gazebo.material</uri>
            <name>Gazebo/Grey</name>
          </script>
        </material>
      </visual>
    </link>
    
            <joint name="chain_r_front_joint" type="fixed">
      <parent>chassis</parent>
      <child>chain_r_front</child>
    </joint>
    <!comment -->
    
    <link name="boardleg_rr">
        <pose>-0.08 -0.08 0.18 0.0 0.0 0.0</pose>
        <collision name="collision">
          <geometry>
            <cylinder>
              <radius>.005</radius>
              <length>.04</length>
            </cylinder>
          </geometry>
        </collision>
        
        <visual name="visual">
          <geometry>
            <cylinder>
              <radius>.005</radius>
              <length>.04</length>
            </cylinder>
          </geometry>
        </visual>
      </link>
      <joint name="leg_rr_joint" type="fixed">
        <child>boardleg_rr</child>
        <parent>boarder</parent>
      </joint>
      
          <link name="boardleg_rl">
        <pose>-0.08 0.08 0.18 0.0 0.0 0.0</pose>
        <collision name="collision">
          <geometry>
            <cylinder>
              <radius>.005</radius>
              <length>.04</length>
            </cylinder>
          </geometry>
        </collision>
        
        <visual name="visual">
          <geometry>
            <cylinder>
              <radius>.005</radius>
              <length>.04</length>
            </cylinder>
          </geometry>
        </visual>
      </link>
      <joint name="leg_rl_joint" type="fixed">
        <child>boardleg_rl</child>
        <parent>boarder</parent>
      </joint>
      
                <link name="boardleg_fl">
        <pose>0.08 0.08 0.18 0.0 0.0 0.0</pose>
        <collision name="collision">
          <geometry>
            <cylinder>
              <radius>.005</radius>
              <length>.04</length>
            </cylinder>
          </geometry>
        </collision>
        
        <visual name="visual">
          <geometry>
            <cylinder>
              <radius>.005</radius>
              <length>.04</length>
            </cylinder>
          </geometry>
        </visual>
      </link>
      <joint name="leg_fl_joint" type="fixed">
        <child>boardleg_fl</child>
        <parent>boarder</parent>
      </joint>
      
                <link name="boardleg_fr">
        <pose>0.08 -0.08 0.18 0.0 0.0 0.0</pose>
        <collision name="collision">
          <geometry>
            <cylinder>
              <radius>.005</radius>
              <length>.04</length>
            </cylinder>
          </geometry>
        </collision>
        
        <visual name="visual">
          <geometry>
            <cylinder>
              <radius>.005</radius>
              <length>.04</length>
            </cylinder>
          </geometry>
        </visual>
      </link>
      <joint name="leg_fr_joint" type="fixed">
        <child>boardleg_fr</child>
        <parent>boarder</parent>
      </joint>
    
    <link name="wheel_fr">
      <pose>
        0.12 -0.1100000000000002 0.05 -1.5707963267948966 0 0
      </pose>
      <inertial>
        <mass>0.25</mass>
        <inertia>
          <ixx>0.00018958333333333338</ixx>
          <iyy>0.00018958333333333338</iyy>
          <izz>0.00031250000000000006</izz>
          <ixy>0</ixy>
          <ixz>0</ixz>
          <iyz>0</iyz>
        </inertia>
      </inertial>
      <collision name="collision">
        <geometry>
          <cylinder>
            <radius>0.05</radius>
            <length>0.02</length>
          </cylinder>
        </geometry>
      </collision>
      <visual name="visual">
        <geometry>
          <cylinder>
            <radius>0.05</radius>
            <length>0.02</length>
          </cylinder>
        </geometry>
        <material>
          <script>
            <uri>file://media/materials/scripts/gazebo.material</uri>
            <name>Gazebo/Black</name>
          </script>
        </material>
      </visual>
    </link>
    
    <joint name="wheel_fr_drive" type="revolute">
      <parent>chassis</parent>
      <child>wheel_fr</child>
      <axis>
        <xyz>0 0 1</xyz>
      </axis>
    </joint>
    
    <link name="wheel_fr2">
      <pose>
        0.2 -0.1100000000000002 0.13 -1.5707963267948966 0 0
      </pose>
      <inertial>
        <mass>0.25</mass>
        <inertia>
          <ixx>0.00018958333333333338</ixx>
          <iyy>0.00018958333333333338</iyy>
          <izz>0.00031250000000000006</izz>
          <ixy>0</ixy>
          <ixz>0</ixz>
          <iyz>0</iyz>
        </inertia>
      </inertial>
      <collision name="collision">
        <geometry>
          <cylinder>
            <radius>0.05</radius>
            <length>0.02</length>
          </cylinder>
        </geometry>
      </collision>
      <visual name="visual">
        <geometry>
          <cylinder>
            <radius>0.05</radius>
            <length>0.02</length>
          </cylinder>
        </geometry>
        <material>
          <script>
            <uri>file://media/materials/scripts/gazebo.material</uri>
            <name>Gazebo/Black</name>
          </script>
        </material>
      </visual>
    </link>
    
    <joint name="wheel_fr2_drive" type="revolute">
      <parent>chassis</parent>
      <child>wheel_fr2</child>
      <axis>
        <xyz>0 0 1</xyz>
      </axis>
    </joint>
    
    
    <link name="wheel_rl">
      <pose>
       -0.1395 0.11100000000000002 0.05 -1.5707963267948966 0 0
      </pose>
      <inertial>
        <mass>0.25</mass>
        <inertia>
          <ixx>0.00018958333333333338</ixx>
          <iyy>0.00018958333333333338</iyy>
          <izz>0.00031250000000000006</izz>
          <ixy>0</ixy>
          <ixz>0</ixz>
          <iyz>0</iyz>
        </inertia>
      </inertial>
      <collision name="collision">
        <geometry>
          <cylinder>
            <radius>0.05</radius>
            <length>0.02</length>
          </cylinder>
        </geometry>
      </collision>
      <visual name="visual">
        <geometry>
          <cylinder>
            <radius>0.05</radius>
            <length>0.02</length>
          </cylinder>
        </geometry>
        <material>
          <script>
            <uri>file://media/materials/scripts/gazebo.material</uri>
            <name>Gazebo/Black</name>
          </script>
        </material>
      </visual>
    </link>
    <joint name="wheel_rl_drive" type="revolute">
      <parent>chassis</parent>
      <child>wheel_rl</child>
      <axis>
        <xyz>0 0 1</xyz>
      </axis>
    </joint>
    
    <link name="wheel_rr">
      <pose>
       -0.1395 -0.1100000000000002 0.05 -1.5707963267948966 0 0
      </pose>
      <inertial>
        <mass>0.25</mass>
        <inertia>
          <ixx>0.00018958333333333338</ixx>
          <iyy>0.00018958333333333338</iyy>
          <izz>0.00031250000000000006</izz>
          <ixy>0</ixy>
          <ixz>0</ixz>
          <iyz>0</iyz>
        </inertia>
      </inertial>
      <collision name="collision">
        <geometry>
          <cylinder>
            <radius>0.05</radius>
            <length>0.02</length>
          </cylinder>
        </geometry>
      </collision>
      <visual name="visual">
        <geometry>
          <cylinder>
            <radius>0.05</radius>
            <length>0.02</length>
          </cylinder>
        </geometry>
        <material>
          <script>
            <uri>file://media/materials/scripts/gazebo.material</uri>
            <name>Gazebo/Black</name>
          </script>
        </material>
      </visual>
    </link>
    <joint name="wheel_rr_drive" type="revolute">
      <parent>chassis</parent>
      <child>wheel_rr</child>
      <axis>
        <xyz>0 0 1</xyz>
      </axis>
    </joint>

   
    <include>
      <uri>model://ultrasonic_sensor</uri>
      <pose>
        0.17 0.0 0.15
        0.0 -0.1 0.0
      </pose>
    </include>

    <joint name="sonar_joint" type="fixed">
      <child>ultrasonic_sensor::link</child>
      <parent>chassis</parent>
    </joint>
    
    <include>
      <uri>model://noisy_imu</uri>
      <pose>
        0.0 0.0 0.16
        0.0 0.0 0.0
      </pose>
    </include>

    <joint name="imu_joint" type="fixed">
      <child>imu::link</child>
      <parent>chassis</parent>
    </joint>
    
 <include>
      <uri>model://camera_sensor</uri>
      <pose>
        0.19 0.0 0.2
        0.0 -0.18 0.0
      </pose>
    </include>

    <joint name="camera_joint" type="fixed">
      <child>camera_sensor::link</child>
      <parent>boarder</parent>
    </joint>
    
  </model>
</sdf>
