<?xml version="1.0" ?>

<sdf version="1.5">
  <!-- http://sdformat.org/spec?elem=sensor&ver=1.5 -->
  <model name="tankbot">
    <link name="chassis">
      <pose>0 0 0.11  0 0 0</pose>
      <inertial>
        <pose>0.04000000000000001 0 0  0 0 0</pose>
        <mass>2.0</mass>
        <inertia>
          <ixx>0.008333333333333335</ixx>
          <iyy>0.02833333333333334</iyy>
          <izz>0.03333333333333334</izz>
          <ixy>0</ixy>
          <ixz>0</ixz>
          <iyz>0</iyz>
        </inertia>
      </inertial>
      <collision name="collision">
        <geometry>
          <box>
            <size>0.4 0.2 0.1</size>
          </box>
        </geometry>
      </collision>
      <visual name='visual'>
        <pose>0 0 0.05 0 0 0</pose>
        <geometry>
          <mesh>
            <uri>model://pioneer2dx/meshes/chassis.dae</uri>
            <scale>0.9 0.5 0.5</scale>
          </mesh>
        </geometry>
      </visual>
      
      <collision name='caster_collision'>
        <pose>0.15 0 -0.05 0 0 0</pose>
        <geometry>
            <sphere>
            <radius>.05</radius>
          </sphere>
        </geometry>
        <surface>
          <friction>
            <ode>
              <mu>0</mu>
              <mu2>0</mu2>
              <slip1>1.0</slip1>
              <slip2>1.0</slip2>
            </ode>
          </friction>
        </surface>
      </collision>

      <visual name='caster_visual'>
        <pose>0.15 0 -0.05 0 0 0</pose>
        <geometry>
          <sphere>
            <radius>.05</radius>
          </sphere>
        </geometry>
      </visual>
    </link>

    
    <link name="wheel_rl">
      <pose>
       -0.12 0.14 0.1
       -1.5707963267948966 0 0
      </pose>
      <inertial>
        <mass>0.25</mass>
        <inertia>
          <ixx>0.0006770833333333335</ixx>
          <iyy>0.0006770833333333335</iyy>
          <izz>0.0012500000000000002</izz>
          <ixy>0</ixy>
          <ixz>0</ixz>
          <iyz>0</iyz>
        </inertia>
      </inertial>
      <collision name="collision">
        <geometry>
          <cylinder>
            <radius>0.1</radius>
            <length>0.05</length>
          </cylinder>
        </geometry>
      </collision>
      <visual name="visual">
        <geometry>
          <cylinder>
            <radius>0.1</radius>
            <length>0.05</length>
          </cylinder>
        </geometry>
        <material>
          <script>
            <uri>file://media/materials/scripts/gazebo.material</uri>
            <name>Gazebo/Black</name>
          </script>
        </material>
      </visual>
    </link>
    <joint name="wheel_rl_drive" type="revolute">
      <parent>chassis</parent>
      <child>wheel_rl</child>
      <axis>
        <xyz>0 0 1</xyz>
      </axis>
    </joint>
    
    <link name="wheel_rr">
      <pose>
       -0.12 -0.14 0.1
       -1.5707963267948966 0 0
      </pose>
      <inertial>
        <mass>0.25</mass>
        <inertia>
          <ixx>0.0006770833333333335</ixx>
          <iyy>0.0006770833333333335</iyy>
          <izz>0.0012500000000000002</izz>
          <ixy>0</ixy>
          <ixz>0</ixz>
          <iyz>0</iyz>
        </inertia>
      </inertial>
      <collision name="collision">
        <geometry>
          <cylinder>
            <radius>0.1</radius>
            <length>0.05</length>
          </cylinder>
        </geometry>
      </collision>
      <visual name="visual">
        <geometry>
          <cylinder>
            <radius>0.1</radius>
            <length>0.05</length>
          </cylinder>
        </geometry>
        <material>
          <script>
            <uri>file://media/materials/scripts/gazebo.material</uri>
            <name>Gazebo/Black</name>
          </script>
        </material>
      </visual>
    </link>
    <joint name="wheel_rr_drive" type="revolute">
      <parent>chassis</parent>
      <child>wheel_rr</child>
      <axis>
        <xyz>0 0 1</xyz>
      </axis>
    </joint>
    
    

    <include>
      <uri>model://ultrasonic_sensor</uri>
      <pose>
        0.15 0.0 0.2
        0.0 0.0 0.0
      </pose>
    </include>

    <joint name="sonar_joint" type="fixed">
      <child>ultrasonic_sensor::link</child>
      <parent>chassis</parent>
    </joint>
    
    <include>
      <uri>model://camera_sensor</uri>
      <pose>
        0.15 0.0 0.3
        0.0 0.0 0.0
      </pose>
    </include>

    <joint name="camera_joint" type="fixed">
      <child>camera_sensor::link</child>
      <parent>chassis</parent>
    </joint>
    
    <include>
      <uri>model://mainboard</uri>
      <pose>
        0.0 0.0 0.0
        0.0 0.0 0.0
      </pose>
    </include>

    <joint name="board_joint" type="fixed">
      <child>mainboard::boarder</child>
      <parent>chassis</parent>
    </joint>
  </model>
</sdf>
